<mujoco model="franka_panda v200">
<!-- =================================================
    Copyright 2018 Vikash Kumar
    Model   :: Franka (MuJoCoV2.0)
    Author  :: Vikash Kumar (vikashplus@gmail.com)
    source  :: https://github.com/vikashplus/franka_sim
    License :: Under Apache License, Version 2.0 (the "License"); you may not use this file except in compliance with the License. You may obtain a copy of the License at http://www.apache.org/licenses/LICENSE-2.0 Unless required by applicable law or agreed to in writing, software distributed under the License is distributed on an "AS IS" BASIS, WITHOUT WARRANTIES OR CONDITIONS OF ANY KIND, either express or implied. See the License for the specific language governing permissions and limitations under the License.
====================================================== -->

    <include file="assets/basic_scene.xml"/>
    <include file="assets/assets.xml"/>
    <compiler meshdir=""/>

    <worldbody>
        <!-- <include file="assets/chain0.xml"/> -->
        
    <body name="panda0_link0" childclass="panda" >
        <geom class="panda_viz" mesh="link0_viz"/>
        <geom class="panda_col" mesh="link0_col" mass="2.91242"/>
        <body name="panda0_link1" pos="0 0 0.333">
            <joint name="panda0_joint1" range="-2.8973 2.8973" class="panda_arm"/>
            <geom class="panda_viz" mesh="link1_viz"/>
            <geom class="panda_col" mesh="link1_col" mass="2.7063"/>
            <body name="panda0_link2" pos="0 0 0" quat="0.707107 -0.707107 0 0">
                <joint name="panda0_joint2" range="-1.7628 1.7628" class="panda_arm"/>
                <geom class="panda_viz" mesh="link2_viz"/>
                <geom class="panda_col" mesh="link2_col" mass="2.73046"/>
                <body name="panda0_link3" pos="0 -0.316 0" quat="0.707107 0.707107 0 0">
                    <joint name="panda0_joint3" range="-2.8973 2.8973" class="panda_arm"/>
                    <geom class="panda_viz" mesh="link3_viz"/>
                    <geom class="panda_grey_viz" mesh="link3_dark_viz" pos="0 .001 0"/>
                    <geom class="panda_col" mesh="link3_col" mass="2.04104"/>
                    <body name="panda0_link4" pos="0.0825 0 0" quat="0.707107 0.707107 0 0">
                        <joint name="panda0_joint4" range="-3.0718 -0.4" class="panda_arm"/>
                        <geom class="panda_viz" mesh="link4_viz"/>
                        <geom class="panda_grey_viz" mesh="link4_dark_viz"/>
                        <geom class="panda_col" mesh="link4_col" mass="2.08129"/>
                        <body name="panda0_link5" pos="-0.0825 0.384 0" quat="0.707107 -0.707107 0 0">
                            <joint name="panda0_joint5" range="-2.8973 2.8973" class="panda_forearm"/>
                            <geom class="panda_viz" mesh="link5_viz"/>
                            <geom class="panda_grey_viz" mesh="link5_dark_viz"/>
                            <geom class="panda_col" mesh="link5_col" mass="3.00049"/>
                            <body name="panda0_link6" pos="0 0 0" euler='1.57 0 1.57'>
                                <joint name="panda0_joint6" range="-1.6573 2.1127" class="panda_forearm"/>
                                <!-- <body name="panda0_link6" pos="0 0 0" quat="0.707107 0.707107 0 0"> -->
                                <!-- <joint name="panda0_joint6" range="-0.0873 3.8223" class="panda_forearm"/> -->
                                <geom class="panda_viz" mesh="link6_viz"/>
                                <geom class="panda_grey_viz" mesh="link6_dark_viz"/>
                                <geom class="panda_col" mesh="link6_col" mass="1.3235"/>
                                <body name="panda0_link7" pos="0.088 0 0" euler='1.57 0 0.7854'>
                                    <joint name="panda0_joint7" range="-2.8973 2.8973" class="panda_forearm"/>
                                    <!-- <body name="panda0_link7" pos="0.088 0 0" quat="0.707107 0.707107 0 0"> -->
                                    <!-- <joint name="panda0_joint7" range="-2.9671 2.9671" class="panda_forearm"/> -->
                                    <geom class="panda_viz" mesh="link7_viz" rgba=".8 .8 .82 1"/>
                                    <geom class="panda_grey_viz" mesh="link7_dark_viz" pos="0 0 -.0008"/>
                                    <geom class="panda_col" mesh="link7_col" mass="0.2"/>
                                    <camera name="Franka_wrist_cam" pos=".050 -.050 0.15" euler="2.95 0.2 -.787"/>
                                    <site name='end_effector' pos='0 0 .210' size='0.01' euler='0 0 -0.785398'/>

                                    <!-- End Effector -->
                                    <body name="panda0_gripper">
                                        <geom pos="0 0 0.107" quat="0.92388 0 0 -0.382683" class="panda_viz" mesh="hand_viz"/>
                                        <geom pos="0 0 0.107" quat="0.92388 0 0 -0.382683" class="panda_col" mesh="hand_col" mass="0.81909"/>

                                    </body>

                                </body>
                            </body>
                        </body>
                    </body>
                </body>
            </body>
        </body>
    </body>
    </worldbody>

    <include file='assets/actuator0.xml'/>

</mujoco>
