<?xml version="1.0"?>
<robot name="three_cube_chain">
  <!-- Base link (fixed cube) -->
  <link name="base">
    <visual>
      <geometry>
        <box size="0.1 0.1 0.1"/>
      </geometry>
      <origin xyz="0 0 0" rpy="0 0 0"/>
      <material name="red">
        <color rgba="1 0 0 1"/>
      </material>
    </visual>
    <collision>
      <geometry>
        <box size="0.1 0.1 0.1"/>
      </geometry>
      <origin xyz="0 0 0" rpy="0 0 0"/>
    </collision>
    <inertial>
      <mass value="1.0"/>
      <inertia ixx="0.00667" ixy="0.0" ixz="0.0" iyy="0.00667" iyz="0.0" izz="0.00667"/>
      <origin xyz="0 0 0" rpy="0 0 0"/>
    </inertial>
  </link>

  <!-- Second link (cube connected by joint1) -->
  <link name="moving1">
    <visual>
      <geometry>
        <box size="0.1 0.1 0.1"/>
      </geometry>
      <origin xyz="0.1 0 0" rpy="0 0 0"/>
      <material name="blue">
        <color rgba="0 0 1 1"/>
      </material>
    </visual>
    <collision>
      <geometry>
        <box size="0.1 0.1 0.1"/>
      </geometry>
      <origin xyz="0.1 0 0" rpy="0 0 0"/>
    </collision>
    <inertial>
      <mass value="1.0"/>
      <inertia ixx="0.00667" ixy="0.0" ixz="0.0" iyy="0.00667" iyz="0.0" izz="0.00667"/>
      <origin xyz="0 0 0" rpy="0 0 0"/>
    </inertial>
  </link>

  <!-- Third link (cube connected by joint2) -->
  <link name="moving2">
    <visual>
      <geometry>
        <box size="0.1 0.1 0.1"/>
      </geometry>
      <origin xyz="0.1 0 0" rpy="0 0 0"/>
      <material name="green">
        <color rgba="0 1 0 1"/>
      </material>
    </visual>
    <collision>
      <geometry>
        <box size="0.1 0.1 0.1"/>
      </geometry>
      <origin xyz="0.1 0 0" rpy="0 0 0"/>
    </collision>
    <inertial>
      <mass value="1.0"/>
      <inertia ixx="0.00667" ixy="0.0" ixz="0.0" iyy="0.00667" iyz="0.0" izz="0.00667"/>
      <origin xyz="0 0 0" rpy="0 0 0"/>
    </inertial>
  </link>

  <!-- Revolute joint connecting base to moving1 (rotates around Z axis) -->
  <joint name="joint1" type="revolute">
    <parent link="base"/>
    <child link="moving1"/>
    <origin xyz="0.1 0 0" rpy="0 0 0"/>
    <axis xyz="0 0 1"/>
    <limit lower="-3.14" upper="3.14" effort="100" velocity="1.0"/>
  </joint>

  <!-- Revolute joint connecting moving1 to moving2 (rotates around Y axis) -->
  <joint name="joint2" type="revolute">
    <parent link="moving1"/>
    <child link="moving2"/>
    <origin xyz="0.2 0 0" rpy="0 0 0"/>
    <axis xyz="0 1 0"/>
    <limit lower="-3.14" upper="3.14" effort="100" velocity="1.0"/>
  </joint>

</robot>
