<mujoco>
    <option gravity="0 0 0" timestep="0.002" />
    <asset>
        <material name="blue_" rgba="0 0 1 1" />
        <material name="green" rgba="0 1 0 1" />
        <material name="red__" rgba="1 0 0 1" />
        <material name="white" rgba="1 1 1 1" />
    </asset>

    <worldbody>
        <light diffuse=".5 .5 .5" pos="0 0 3" dir="0 0 -1" />
        <body name="link_1" pos="0 0 2" euler="20 20 20">
            <geom type="cylinder" size=".2    2" pos="0 0 2" euler="0 0 0" material="red__"/>
            <geom type="cylinder" size=".25 .25" pos="0 0 4" euler="0 90 0" material="red__"/>
            <geom type="cylinder" size=".25 .25" pos="0 0 0" euler="0 90 0" material="red__"/>
            <body name="link_2" pos="0.5 0 0" euler="0 0 0">
                <joint name="hinge_1" pos="0 0 0" axis="1 0 0" />
                <geom type="cylinder" size=".2    2" pos="0 2 0" euler="90 0 0" material="blue_"/>
                <geom type="cylinder" size=".25 .25" pos="0 4 0" euler="0 90 0" material="blue_"/>
                <geom type="cylinder" size=".25 .25" pos="0 0 0" euler="0 90 0" material="blue_"/>
                <body name="link_3" pos="-0.5 4 0" euler="0 0 0">
                    <joint name="hinge_2" pos="0 0 0" axis="1 0 0" />
                    <geom type="cylinder" size=".2    2" pos="0 0 2" euler="0 0 0" material="green"/>
                    <geom type="cylinder" size=".25 .25" pos="0 0 0" euler="0 90 0" material="green"/>
                    <geom type="cylinder" size=".25 .25" pos="0 0 4" euler="0 90 0" material="green"/>
                    <body name="link_4" pos="0.5 0 4" euler="0 0 0">
                        <joint name="hinge_3" pos="0 0 0" axis="1 0 0" />
                        <geom type="cylinder" size=".2    2" pos="0 -2 0" euler="90 0 0" material="white"/>
                        <geom type="cylinder" size=".25 .25" pos="0 0 0" euler="0 90 0" material="white"/>
                        <geom type="cylinder" size=".25 .25" pos="0 -4 0" euler="0 90 0" material="white"/>
                    </body>
                </body>
            </body>
        </body>
    </worldbody>
    <equality>
        <weld name="kinematic_link1" active="true" body1="link_1" body2="link_4" anchor="0 0 4" />
        <!-- <connect name="kinematic_link1" active="true" body1="link_1" body2="link_4" anchor="0 0 4" /> -->
    </equality>

</mujoco>