<mujoco model="capsule_rope">
  <compiler angle="degree"/>
  <option gravity="0 0 -9.81"/>
  <default>
    <default class="/">
      <joint damping="0.01"/>
      <geom friction="1 0.005 0.0001" density="500"/>
    </default>
  </default>

  <worldbody>
    <body name="seg0" pos="0 0 0.2" euler="45 45 45">
      <geom name="seg0_geom" class="/" type="capsule" size="0.02 0.05" rgba="1 0 0 1" fromto="-0 0 0 0.1 0 0"/>
      <body name="seg1" pos="0.1 0 0">
        <joint name="ball1" class="/" type="ball" stiffness="0"/>
        <geom name="seg1_geom" class="/" type="capsule" size="0.02 0.05" rgba="0 1 0 1" fromto="-0 0 0 0.1 0 0"/>
      </body>
    </body>
  </worldbody>
</mujoco>
